test2 = 2
raise Exception('some exception')
